Workbook

Sheet Roth IRA
A1: Description (Sleeve) | B1: Ticker | C1: Weight | D1: Shares | E1: Worth | F1: Avg Cost | G1: Div Yield | H1: Div Growth | I1: Type | J1: Dividend | K1: Link | L1: Return | M1: Account | N1: Expense Ratio | O1: Order | P1: Contributions | Q1: 46055 | R1: 39221.21 | U1: Exposure | V1: {=UNIQUE(A:A)} -> Description (Sleeve) | W1: Breakdown | X1: Worth | Y1: Cost | Z1: Dividends | AA1: Returns | AB1: Fees | AC1: Dividend Yield
A2: US Indices | B2: FXAIX | C2: =E2/$Q$16 -> 0.23278094 | D2: 38.904 | E2: =IFERROR(__xludf.DUMMYFUNCTION("(GOOGLEFINANCE(B2)*D2)"),10153.554960000001) -> 10153.555 | F2: =(240.05*D2) -> 9338.9052 | G2: =IFERROR(VLOOKUP(B2,'Stock Stats'!$A:$M,6,false),"") -> 0.010575118 | H2: =IFERROR(VLOOKUP(B2,'Stock Stats'!$A:$M,8,false),"") -> 0.051 | I2: mutf | J2: =((E2*G2)) -> 107.37504 | K2: =IF(I2="mutf","https://stockanalysis.com/quote/"&I2&"/"&B2&"/dividend/","https://stockanalysis.com/"&I2&"/"&B2&"/dividend/") -> https://stockanalysis.com/quote/mutf/FXAIX/dividend/ | L2: =(E2-F2)/F2 -> 0.087231827 | M2: Fidelity | N2: =IFERROR(E2*VLOOKUP(B2,'Stock Stats'!$A:$M,11,false),"") -> 1.5230332 | O2: 1 | U2: =IFERROR(SUMIF($A$2:$A21,V2,$C$2:$C21),"") -> 0.23278094 | V2: US Indices | W2: {=TEXTJOIN(", ", TRUE, IF($A:$A=V2, $B:$B&" ("&TEXT($C:$C,"0.00%")&")", ""))} -> FXAIX (23.28%) | X2: =IFERROR(SUMIF($A$2:$A21,V2,$E$2:$E21),"") -> 10153.555 | Y2: =IFERROR(SUMIF($A$2:$A21,V2,$F$2:$F21),"") -> 9338.9052 | Z2: =IFERROR(SUMIF($A$2:$A21,V2,$J$2:$J21),"") -> 107.37504 | AA2: =(X2-Y2)/Y2 -> 0.087231827 | AB2: =IFERROR(SUMIF($A$2:$A21,V2,$N$2:$N21),"") -> 1.5230332 | AC2: =Z2/X2 -> 0.010575118
A3: Large Cap Growth | B3: NVDA | C3: =E3/$Q$16 -> 0.026831716 | D3: 5.519 | E3: =IFERROR(__xludf.DUMMYFUNCTION("(GOOGLEFINANCE(B3)*D3)"),1170.35914) -> 1170.3591 | F3: =(183.56*D3) -> 1013.0676 | G3: =IFERROR(VLOOKUP(B3,'Stock Stats'!$A:$M,6,false),"") -> 0.00018862586 | H3: =IFERROR(VLOOKUP(B3,'Stock Stats'!$A:$M,8,false),"") -> 6 | I3: stocks | J3: =((E3*G3)) -> 0.22076 | K3: =IF(I3="mutf","https://stockanalysis.com/quote/"&I3&"/"&B3&"/dividend/","https://stockanalysis.com/"&I3&"/"&B3&"/dividend/") -> https://stockanalysis.com/stocks/NVDA/dividend/ | L3: =(E3-F3)/F3 -> 0.15526258 | M3: Fidelity | N3: =IFERROR(E3*VLOOKUP(B3,'Stock Stats'!$A:$M,11,false),"") -> 0 | O3: 2 | U3: =IFERROR(SUMIF($A$2:$A22,V3,$C$2:$C22),"") -> 0.085413136 | V3: Large Cap Growth | W3: {=TEXTJOIN(", ", TRUE, IF($A:$A=V3, $B:$B&" ("&TEXT($C:$C,"0.00%")&")", ""))} -> NVDA (2.68%), MSFT (0.94%), GARP (4.92%) | X3: =IFERROR(SUMIF($A$2:$A22,V3,$E$2:$E22),"") -> 3725.5927 | Y3: =IFERROR(SUMIF($A$2:$A22,V3,$F$2:$F22),"") -> 3402.6773 | Z3: =IFERROR(SUMIF($A$2:$A22,V3,$J$2:$J22),"") -> 41.49685 | AA3: =(X3-Y3)/Y3 -> 0.094900383 | AB3: =IFERROR(SUMIF($A$2:$A22,V3,$N$2:$N22),"") -> 3.2174793 | AC3: =Z3/X3 -> 0.011138322
A4: Large Cap Growth | B4: MSFT | C4: =E4/$Q$16 -> 0.0094053523 | D4: 1.051 | E4: =IFERROR(__xludf.DUMMYFUNCTION("(GOOGLEFINANCE(B4)*D4)"),410.24733999999995) -> 410.24734 | F4: =(370.78*D4) -> 389.68978 | G4: =IFERROR(VLOOKUP(B4,'Stock Stats'!$A:$M,6,false),"") -> 0.0068658093 | H4: =IFERROR(VLOOKUP(B4,'Stock Stats'!$A:$M,8,false),"") -> 0.0964 | I4: stocks | J4: =((E4*G4)) -> 2.81668 | K4: =IF(I4="mutf","https://stockanalysis.com/quote/"&I4&"/"&B4&"/dividend/","https://stockanalysis.com/"&I4&"/"&B4&"/dividend/") -> https://stockanalysis.com/stocks/MSFT/dividend/ | L4: =(E4-F4)/F4 -> 0.052753654 | M4: Fidelity | N4: =IFERROR(E4*VLOOKUP(B4,'Stock Stats'!$A:$M,11,false),"") -> 0 | O4: 2 | U4: =IFERROR(SUMIF($A$2:$A23,V4,$C$2:$C23),"") -> 0.22620005 | V4: Concentrated Tech Growth | W4: {=TEXTJOIN(", ", TRUE, IF($A:$A=V4, $B:$B&" ("&TEXT($C:$C,"0.00%")&")", ""))} -> VGT (13.00%), QQQM (9.62%) | X4: =IFERROR(SUMIF($A$2:$A23,V4,$E$2:$E23),"") -> 9866.5064 | Y4: =IFERROR(SUMIF($A$2:$A23,V4,$F$2:$F23),"") -> 8371.7596 | Z4: =IFERROR(SUMIF($A$2:$A23,V4,$J$2:$J23),"") -> 40.01484 | AA4: =(X4-Y4)/Y4 -> 0.17854631 | AB4: =IFERROR(SUMIF($A$2:$A23,V4,$N$2:$N23),"") -> 11.396577 | AC4: =Z4/X4 -> 0.004055624
A5: Concentrated Tech Growth | B5: VGT | C5: =E5/$Q$16 -> 0.13003589 | D5: 49.057 | E5: =IFERROR(__xludf.DUMMYFUNCTION("(GOOGLEFINANCE(B5)*D5)"),5671.970340000001) -> 5671.9703 | F5: =(93.55*D5) -> 4589.2824 | G5: =IFERROR(VLOOKUP(B5,'Stock Stats'!$A:$M,6,false),"") -> 0.0037190797 | H5: =IFERROR(VLOOKUP(B5,'Stock Stats'!$A:$M,8,false),"") -> 0.109 | I5: etf | J5: =((E5*G5)) -> 21.09451 | K5: =IF(I5="mutf","https://stockanalysis.com/quote/"&I5&"/"&B5&"/dividend/","https://stockanalysis.com/"&I5&"/"&B5&"/dividend/") -> https://stockanalysis.com/etf/VGT/dividend/ | L5: =(E5-F5)/F5 -> 0.23591662 | M5: Fidelity | N5: =IFERROR(E5*VLOOKUP(B5,'Stock Stats'!$A:$M,11,false),"") -> 5.1047733 | O5: 3 | U5: =IFERROR(SUMIF($A$2:$A24,V5,$C$2:$C24),"") -> 0.20277118 | V5: Speculative Tech Growth | W5: {=TEXTJOIN(", ", TRUE, IF($A:$A=V5, $B:$B&" ("&TEXT($C:$C,"0.00%")&")", ""))} -> WQTM (4.40%), QTUM (15.88%) | X5: =IFERROR(SUMIF($A$2:$A24,V5,$E$2:$E24),"") -> 8844.5745 | Y5: =IFERROR(SUMIF($A$2:$A24,V5,$F$2:$F24),"") -> 8191.2881 | Z5: =IFERROR(SUMIF($A$2:$A24,V5,$J$2:$J24),"") -> 56.43468 | AA5: =(X5-Y5)/Y5 -> 0.079753801 | AB5: =IFERROR(SUMIF($A$2:$A24,V5,$N$2:$N24),"") -> 36.337265 | AC5: =Z5/X5 -> 0.0063807117
A6: Concentrated Tech Growth | B6: QQQM | C6: =E6/$Q$16 -> 0.096164157 | D6: 14.443 | E6: =IFERROR(__xludf.DUMMYFUNCTION("(GOOGLEFINANCE(B6)*D6)"),4194.53606) -> 4194.5361 | F6: =(261.89*D6) -> 3782.4773 | G6: =IFERROR(VLOOKUP(B6,'Stock Stats'!$A:$M,6,false),"") -> 0.0045107086 | H6: =IFERROR(VLOOKUP(B6,'Stock Stats'!$A:$M,8,false),"") -> 0.0494 | I6: etf | J6: =((E6*G6)) -> 18.92033 | K6: =IF(I6="mutf","https://stockanalysis.com/quote/"&I6&"/"&B6&"/dividend/","https://stockanalysis.com/"&I6&"/"&B6&"/dividend/") -> https://stockanalysis.com/etf/QQQM/dividend/ | L6: =(E6-F6)/F6 -> 0.10893887 | M6: Fidelity | N6: =IFERROR(E6*VLOOKUP(B6,'Stock Stats'!$A:$M,11,false),"") -> 6.2918041 | O6: 3 | U6: =IFERROR(SUMIF($A$2:$A25,V6,$C$2:$C25),"") -> 0.12865761 | V6: Dividend Equity | W6: {=TEXTJOIN(", ", TRUE, IF($A:$A=V6, $B:$B&" ("&TEXT($C:$C,"0.00%")&")", ""))} -> SCHD (12.87%) | X6: =IFERROR(SUMIF($A$2:$A25,V6,$E$2:$E25),"") -> 5611.8517 | Y6: =IFERROR(SUMIF($A$2:$A25,V6,$F$2:$F25),"") -> 5280.9401 | Z6: =IFERROR(SUMIF($A$2:$A25,V6,$J$2:$J25),"") -> 179.10165 | AA6: =(X6-Y6)/Y6 -> 0.062661499 | AB6: =IFERROR(SUMIF($A$2:$A25,V6,$N$2:$N25),"") -> 3.367111 | AC6: =Z6/X6 -> 0.031914894
A7: Large Cap Growth | B7: GARP | C7: =E7/$Q$16 -> 0.049176068 | D7: 26.964 | E7: =IFERROR(__xludf.DUMMYFUNCTION("(GOOGLEFINANCE(""BATS:GARP"")*D7)"),2144.9862) -> 2144.9862 | F7: =(74.17*D7) -> 1999.9199 | G7: =IFERROR(VLOOKUP(B7,'Stock Stats'!$A:$M,6,false),"") -> 0.01792991 | H7: =IFERROR(VLOOKUP(B7,'Stock Stats'!$A:$M,8,false),"") -> 0 | I7: etf | J7: =((E7*G7)) -> 38.45941 | K7: =IF(I7="mutf","https://stockanalysis.com/quote/"&I7&"/"&B7&"/dividend/","https://stockanalysis.com/"&I7&"/"&B7&"/dividend/") -> https://stockanalysis.com/etf/GARP/dividend/ | L7: =(E7-F7)/F7 -> 0.072536066 | M7: Fidelity | N7: =IFERROR(E7*VLOOKUP(B7,'Stock Stats'!$A:$M,11,false),"") -> 3.2174793 | O7: 3 | U7: =IFERROR(SUMIF($A$2:$A26,V7,$C$2:$C26),"") -> 0.092946481 | V7: International | W7: {=TEXTJOIN(", ", TRUE, IF($A:$A=V7, $B:$B&" ("&TEXT($C:$C,"0.00%")&")", ""))} -> VEA (4.71%), VWO (3.64%), FLMX (0.94%) | X7: =IFERROR(SUMIF($A$2:$A26,V7,$E$2:$E26),"") -> 4054.1859 | Y7: =IFERROR(SUMIF($A$2:$A26,V7,$F$2:$F26),"") -> 3887.7141 | Z7: =IFERROR(SUMIF($A$2:$A26,V7,$J$2:$J26),"") -> 105.65804 | AA7: =(X7-Y7)/Y7 -> 0.042819959 | AB7: =IFERROR(SUMIF($A$2:$A26,V7,$N$2:$N26),"") -> 2.3503919 | AC7: =Z7/X7 -> 0.026061469
A8: Speculative Tech Growth | B8: WQTM | C8: =E8/$Q$16 -> 0.043970677 | D8: 59.786 | E8: =IFERROR(__xludf.DUMMYFUNCTION("(GOOGLEFINANCE(""BATS:WQTM"")*D8)"),1917.93488) -> 1917.9349 | F8: =(36.88*D8) -> 2204.9077 | G8: =IFERROR(VLOOKUP(B8,'Stock Stats'!$A:$M,6,false),"") -> 0 | H8: =IFERROR(VLOOKUP(B8,'Stock Stats'!$A:$M,8,false),"") -> 0 | I8: etf | J8: =((E8*G8)) -> 0 | K8: =IF(I8="mutf","https://stockanalysis.com/quote/"&I8&"/"&B8&"/dividend/","https://stockanalysis.com/"&I8&"/"&B8&"/dividend/") -> https://stockanalysis.com/etf/WQTM/dividend/ | L8: =(E8-F8)/F8 -> -0.13015184 | M8: Fidelity | N8: =IFERROR(E8*VLOOKUP(B8,'Stock Stats'!$A:$M,11,false),"") -> 8.630707 | O8: 4 | U8: =IFERROR(SUMIF($A$2:$A27,V8,$C$2:$C27),"") -> 0.031201251 | V8: Future of Electrification | W8: {=TEXTJOIN(", ", TRUE, IF($A:$A=V8, $B:$B&" ("&TEXT($C:$C,"0.00%")&")", ""))} -> POWR (3.12%) | X8: =IFERROR(SUMIF($A$2:$A27,V8,$E$2:$E27),"") -> 1360.9517 | Y8: =IFERROR(SUMIF($A$2:$A27,V8,$F$2:$F27),"") -> 1347.7975 | Z8: =IFERROR(SUMIF($A$2:$A27,V8,$J$2:$J27),"") -> 76.39543 | AA8: =(X8-Y8)/Y8 -> 0.0097597598 | AB8: =IFERROR(SUMIF($A$2:$A27,V8,$N$2:$N27),"") -> 5.4438068 | AC8: =Z8/X8 -> 0.056133829
A9: Speculative Tech Growth | B9: QTUM | C9: =E9/$Q$16 -> 0.15880051 | D9: 47.826 | E9: =IFERROR(__xludf.DUMMYFUNCTION("(GOOGLEFINANCE(B9)*D9)"),6926.639580000001) -> 6926.6396 | F9: =(125.17*D9) -> 5986.3804 | G9: =IFERROR(VLOOKUP(B9,'Stock Stats'!$A:$M,6,false),"") -> 0.0081474833 | H9: =IFERROR(VLOOKUP(B9,'Stock Stats'!$A:$M,8,false),"") -> 0.9109 | I9: etf | J9: =((E9*G9)) -> 56.43468 | K9: =IF(I9="mutf","https://stockanalysis.com/quote/"&I9&"/"&B9&"/dividend/","https://stockanalysis.com/"&I9&"/"&B9&"/dividend/") -> https://stockanalysis.com/etf/QTUM/dividend/ | L9: =(E9-F9)/F9 -> 0.15706639 | M9: Fidelity | N9: =IFERROR(E9*VLOOKUP(B9,'Stock Stats'!$A:$M,11,false),"") -> 27.706558 | O9: 4
A10: Dividend Equity | B10: SCHD | C10: =E10/$Q$16 -> 0.12865761 | D10: 170.573 | E10: =IFERROR(__xludf.DUMMYFUNCTION("(GOOGLEFINANCE(B10)*D10)"),5611.8517) -> 5611.8517 | F10: =(30.96*D10) -> 5280.9401 | G10: =IFERROR(VLOOKUP(B10,'Stock Stats'!$A:$M,6,false),"") -> 0.031914894 | H10: =IFERROR(VLOOKUP(B10,'Stock Stats'!$A:$M,8,false),"") -> 0.0224 | I10: etf | J10: =((E10*G10)) -> 179.10165 | K10: =IF(I10="mutf","https://stockanalysis.com/quote/"&I10&"/"&B10&"/dividend/","https://stockanalysis.com/"&I10&"/"&B10&"/dividend/") -> https://stockanalysis.com/etf/SCHD/dividend/ | L10: =(E10-F10)/F10 -> 0.062661499 | M10: Fidelity | N10: =IFERROR(E10*VLOOKUP(B10,'Stock Stats'!$A:$M,11,false),"") -> 3.367111 | O10: 5
A11: International | B11: VEA | C11: =E11/$Q$16 -> 0.047117772 | D11: 29.156 | E11: =IFERROR(__xludf.DUMMYFUNCTION("(GOOGLEFINANCE(B11)*D11)"),2055.20644) -> 2055.2064 | F11: =(66.88*D11) -> 1949.9533 | G11: =IFERROR(VLOOKUP(B11,'Stock Stats'!$A:$M,6,false),"") -> 0.025677401 | H11: =IFERROR(VLOOKUP(B11,'Stock Stats'!$A:$M,8,false),"") -> 0.1772 | I11: etf | J11: =((E11*G11)) -> 52.77236 | K11: =IF(I11="mutf","https://stockanalysis.com/quote/"&I11&"/"&B11&"/dividend/","https://stockanalysis.com/"&I11&"/"&B11&"/dividend/") -> https://stockanalysis.com/etf/VEA/dividend/ | L11: =(E11-F11)/F11 -> 0.053977273 | M11: Fidelity | N11: =IFERROR(E11*VLOOKUP(B11,'Stock Stats'!$A:$M,11,false),"") -> 0.61656193 | O11: 6
A12: International | B12: VWO | C12: =E12/$Q$16 -> 0.036403592 | D12: 27 | E12: =IFERROR(__xludf.DUMMYFUNCTION("(GOOGLEFINANCE(B12)*D12)"),1587.8700000000001) -> 1587.87 | F12: =(56.4*D12) -> 1522.8 | G12: =IFERROR(VLOOKUP(B12,'Stock Stats'!$A:$M,6,false),"") -> 0.023465397 | H12: =IFERROR(VLOOKUP(B12,'Stock Stats'!$A:$M,8,false),"") -> -0.0017 | I12: etf | J12: =((E12*G12)) -> 37.26 | K12: =IF(I12="mutf","https://stockanalysis.com/quote/"&I12&"/"&B12&"/dividend/","https://stockanalysis.com/"&I12&"/"&B12&"/dividend/") -> https://stockanalysis.com/etf/VWO/dividend/ | L12: =(E12-F12)/F12 -> 0.042730496 | M12: Fidelity | N12: =IFERROR(E12*VLOOKUP(B12,'Stock Stats'!$A:$M,11,false),"") -> 0.952722 | O12: 6
A13: International | B13: FLMX | C13: =E13/$Q$16 -> 0.0094251169 | D13: 11.004 | E13: =IFERROR(__xludf.DUMMYFUNCTION("(GOOGLEFINANCE(B13)*D13)"),411.10943999999995) -> 411.10944 | F13: =(37.71*D13) -> 414.96084 | G13: =IFERROR(VLOOKUP(B13,'Stock Stats'!$A:$M,6,false),"") -> 0.038008565 | H13: =IFERROR(VLOOKUP(B13,'Stock Stats'!$A:$M,8,false),"") -> 0.1577 | I13: etf | J13: =((E13*G13)) -> 15.62568 | K13: =IF(I13="mutf","https://stockanalysis.com/quote/"&I13&"/"&B13&"/dividend/","https://stockanalysis.com/"&I13&"/"&B13&"/dividend/") -> https://stockanalysis.com/etf/FLMX/dividend/ | L13: =(E13-F13)/F13 -> -0.0092813577 | M13: Fidelity | N13: =IFERROR(E13*VLOOKUP(B13,'Stock Stats'!$A:$M,11,false),"") -> 0.78110794 | O13: 6
A14: Future of Electrification | B14: POWR | C14: =E14/$Q$16 -> 0.031201251 | D14: 50.593 | E14: =IFERROR(__xludf.DUMMYFUNCTION("(GOOGLEFINANCE(B14)*D14)"),1360.9517) -> 1360.9517 | F14: =(26.64*D14) -> 1347.7975 | G14: =IFERROR(VLOOKUP(B14,'Stock Stats'!$A:$M,6,false),"") -> 0.056133829 | H14: =IFERROR(VLOOKUP(B14,'Stock Stats'!$A:$M,8,false),"") -> 0.4922 | I14: etf | J14: =((E14*G14)) -> 76.39543 | K14: =IF(I14="mutf","https://stockanalysis.com/quote/"&I14&"/"&B14&"/dividend/","https://stockanalysis.com/"&I14&"/"&B14&"/dividend/") -> https://stockanalysis.com/etf/POWR/dividend/ | L14: =(E14-F14)/F14 -> 0.0097597598 | M14: Fidelity | N14: =IFERROR(E14*VLOOKUP(B14,'Stock Stats'!$A:$M,11,false),"") -> 5.4438068 | O14: 7 | Q14: Cash | R14: 1.28 | S14: Return
N15: =IFERROR(E15*VLOOKUP(B15,Investments!$AC:$AM,10,false),"") | Q15: Total Worth | R15: Total Paid | S15: =(Q16-R16)/R16 -> 0.11211505
N16: =IFERROR(E16*VLOOKUP(B16,Investments!$AC:$AM,10,false),"") | Q16: =SUM($E$2:$E21)+R14 -> 43618.498 | R16: =SUM(R1:R2) -> 39221.21 | S16: =Q16-R16 -> 4397.2878
N17: =IFERROR(E17*VLOOKUP(B17,Investments!$AC:$AM,10,false),"")
N18: =IFERROR(E18*VLOOKUP(B18,Investments!$AC:$AM,10,false),"")
N19: =IFERROR(E19*VLOOKUP(B19,Investments!$AC:$AM,10,false),"")
N20: =IFERROR(E20*VLOOKUP(B20,Investments!$AC:$AM,10,false),"")
N21: =IFERROR(E21*VLOOKUP(B21,Investments!$AC:$AM,10,false),"")

Sheet Traditional IRA
A1: Description | B1: Ticker | C1: Weight | D1: Shares | E1: Worth | F1: Avg Cost | G1: Div Yield | H1: Div Growth | I1: Type | J1: Dividend | K1: Link | L1: Return | M1: Account | N1: Expense Ratio | O1: Order | U1: Exposure | V1: {=UNIQUE(A:A)} -> Description | W1: Breakdown | X1: Worth | Y1: Cost | Z1: Dividends | AA1: Returns | AB1: Fees | AC1: Dividend Yield
A2: S&P 500 | B2: SPYM | C2: =E2/$Q$16 -> 0.30033621 | D2: 276.2793 | E2: =IFERROR(__xludf.DUMMYFUNCTION("(GOOGLEFINANCE(B2)*D2)"),24304.290020999997) -> 24304.29 | F2: 23872 | G2: =IFERROR(VLOOKUP(B2,'Stock Stats'!$A:$M,6,false),"") -> 0.010344436 | H2: =IFERROR(VLOOKUP(B2,'Stock Stats'!$A:$M,8,false),"") -> 0.0275 | I2: etf | J2: =((E2*G2)) -> 251.41416 | K2: =IF(I2="mutf","https://stockanalysis.com/quote/"&I2&"/"&B2&"/dividend/","https://stockanalysis.com/"&I2&"/"&B2&"/dividend/") -> https://stockanalysis.com/etf/SPYM/dividend/ | L2: =(E2-F2)/F2 -> 0.018108664 | M2: Charles Schwab | N2: =IFERROR(E2*VLOOKUP(B2,'Stock Stats'!$A:$M,11,false),"") -> 4.860858 | O2: 1 | U2: =IFERROR(SUMIF($A$2:$A18,V2,$C$2:$C18),"") -> 0.30033621 | V2: S&P 500 | W2: {=TEXTJOIN(", ", TRUE, IF($A:$A=V2, $B:$B&" ("&TEXT($C:$C,"0.00%")&")", ""))} -> SPYM (30.03%) | X2: =IFERROR(SUMIF($A$2:$A18,V2,$E$2:$E18),"") -> 24304.29 | Y2: =IFERROR(SUMIF($A$2:$A18,V2,$F$2:$F18),"") -> 23872 | Z2: =IFERROR(SUMIF($A$2:$A18,V2,$J$2:$J18),"") -> 251.41416 | AA2: =(X2-Y2)/Y2 -> 0.018108664 | AB2: =IFERROR(SUMIF($A$2:$A18,V2,$N$2:$N18),"") -> 4.860858 | AC2: =Z2/Y2 -> 0.01053176
A3: NASDAQ 100 | B3: QQQM | C3: =E3/$Q$16 -> 0.10470983 | D3: 29.1767 | E3: =IFERROR(__xludf.DUMMYFUNCTION("(GOOGLEFINANCE(B3)*D3)"),8473.497214) -> 8473.4972 | F3: 8259.63 | G3: =IFERROR(VLOOKUP(B3,'Stock Stats'!$A:$M,6,false),"") -> 0.0045107086 | H3: =IFERROR(VLOOKUP(B3,'Stock Stats'!$A:$M,8,false),"") -> 0.0494 | I3: etf | J3: =((E3*G3)) -> 38.221477 | K3: =IF(I3="mutf","https://stockanalysis.com/quote/"&I3&"/"&B3&"/dividend/","https://stockanalysis.com/"&I3&"/"&B3&"/dividend/") -> https://stockanalysis.com/etf/QQQM/dividend/ | L3: =(E3-F3)/F3 -> 0.025893074 | M3: Charles Schwab | N3: =IFERROR(E3*VLOOKUP(B3,'Stock Stats'!$A:$M,11,false),"") -> 12.710246 | O3: 2 | U3: =IFERROR(SUMIF($A$2:$A19,V3,$C$2:$C19),"") -> 0.10470983 | V3: NASDAQ 100 | W3: {=TEXTJOIN(", ", TRUE, IF($A:$A=V3, $B:$B&" ("&TEXT($C:$C,"0.00%")&")", ""))} -> QQQM (10.47%) | X3: =IFERROR(SUMIF($A$2:$A19,V3,$E$2:$E19),"") -> 8473.4972 | Y3: =IFERROR(SUMIF($A$2:$A19,V3,$F$2:$F19),"") -> 8259.63 | Z3: =IFERROR(SUMIF($A$2:$A19,V3,$J$2:$J19),"") -> 38.221477 | AA3: =(X3-Y3)/Y3 -> 0.025893074 | AB3: =IFERROR(SUMIF($A$2:$A19,V3,$N$2:$N19),"") -> 12.710246 | AC3: =Z3/Y3 -> 0.0046275047
A4: Technology ETF | B4: VGT | C4: =E4/$Q$16 -> 0.10857065 | D4: 75.9897 | E4: =IFERROR(__xludf.DUMMYFUNCTION("(GOOGLEFINANCE(B4)*D4)"),8785.929114) -> 8785.9291 | F4: 8206.49 | G4: =IFERROR(VLOOKUP(B4,'Stock Stats'!$A:$M,6,false),"") -> 0.0037190797 | H4: =IFERROR(VLOOKUP(B4,'Stock Stats'!$A:$M,8,false),"") -> 0.109 | I4: etf | J4: =((E4*G4)) -> 32.675571 | K4: =IF(I4="mutf","https://stockanalysis.com/quote/"&I4&"/"&B4&"/dividend/","https://stockanalysis.com/"&I4&"/"&B4&"/dividend/") -> https://stockanalysis.com/etf/VGT/dividend/ | L4: =(E4-F4)/F4 -> 0.070607423 | M4: Charles Schwab | N4: =IFERROR(E4*VLOOKUP(B4,'Stock Stats'!$A:$M,11,false),"") -> 7.9073362 | O4: 3 | U4: =IFERROR(SUMIF($A$2:$A20,V4,$C$2:$C20),"") -> 0.10857065 | V4: Technology ETF | W4: {=TEXTJOIN(", ", TRUE, IF($A:$A=V4, $B:$B&" ("&TEXT($C:$C,"0.00%")&")", ""))} -> VGT (10.86%) | X4: =IFERROR(SUMIF($A$2:$A20,V4,$E$2:$E20),"") -> 8785.9291 | Y4: =IFERROR(SUMIF($A$2:$A20,V4,$F$2:$F20),"") -> 8206.49 | Z4: =IFERROR(SUMIF($A$2:$A20,V4,$J$2:$J20),"") -> 32.675571 | AA4: =(X4-Y4)/Y4 -> 0.070607423 | AB4: =IFERROR(SUMIF($A$2:$A20,V4,$N$2:$N20),"") -> 7.9073362 | AC4: =Z4/Y4 -> 0.0039816744
A5: Quantum ETF | B5: QTUM | C5: =E5/$Q$16 -> 0.16245812 | D5: 90.7733 | E5: =IFERROR(__xludf.DUMMYFUNCTION("(GOOGLEFINANCE(B5)*D5)"),13146.697039000002) -> 13146.697 | F5: 12730.82 | G5: =IFERROR(VLOOKUP(B5,'Stock Stats'!$A:$M,6,false),"") -> 0.0081474833 | H5: =IFERROR(VLOOKUP(B5,'Stock Stats'!$A:$M,8,false),"") -> 0.9109 | I5: etf | J5: =((E5*G5)) -> 107.11249 | K5: =IF(I5="mutf","https://stockanalysis.com/quote/"&I5&"/"&B5&"/dividend/","https://stockanalysis.com/"&I5&"/"&B5&"/dividend/") -> https://stockanalysis.com/etf/QTUM/dividend/ | L5: =(E5-F5)/F5 -> 0.032666948 | M5: Charles Schwab | N5: =IFERROR(E5*VLOOKUP(B5,'Stock Stats'!$A:$M,11,false),"") -> 52.586788 | O5: 4 | U5: =IFERROR(SUMIF($A$2:$A21,V5,$C$2:$C21),"") -> 0.16245812 | V5: Quantum ETF | W5: {=TEXTJOIN(", ", TRUE, IF($A:$A=V5, $B:$B&" ("&TEXT($C:$C,"0.00%")&")", ""))} -> QTUM (16.25%) | X5: =IFERROR(SUMIF($A$2:$A21,V5,$E$2:$E21),"") -> 13146.697 | Y5: =IFERROR(SUMIF($A$2:$A21,V5,$F$2:$F21),"") -> 12730.82 | Z5: =IFERROR(SUMIF($A$2:$A21,V5,$J$2:$J21),"") -> 107.11249 | AA5: =(X5-Y5)/Y5 -> 0.032666948 | AB5: =IFERROR(SUMIF($A$2:$A21,V5,$N$2:$N21),"") -> 52.586788 | AC5: =Z5/Y5 -> 0.0084136367
A6: Dividends Kings ETF | B6: SCHD | C6: =E6/$Q$16 -> 0.2577672 | D6: 634.0259 | E6: =IFERROR(__xludf.DUMMYFUNCTION("(GOOGLEFINANCE(B6)*D6)"),20859.45211) -> 20859.452 | F6: 19997.33 | G6: =IFERROR(VLOOKUP(B6,'Stock Stats'!$A:$M,6,false),"") -> 0.031914894 | H6: =IFERROR(VLOOKUP(B6,'Stock Stats'!$A:$M,8,false),"") -> 0.0224 | I6: etf | J6: =((E6*G6)) -> 665.7272 | K6: =IF(I6="mutf","https://stockanalysis.com/quote/"&I6&"/"&B6&"/dividend/","https://stockanalysis.com/"&I6&"/"&B6&"/dividend/") -> https://stockanalysis.com/etf/SCHD/dividend/ | L6: =(E6-F6)/F6 -> 0.043111861 | M6: Charles Schwab | N6: =IFERROR(E6*VLOOKUP(B6,'Stock Stats'!$A:$M,11,false),"") -> 12.515671 | O6: 5 | U6: =IFERROR(SUMIF($A$2:$A22,V6,$C$2:$C22),"") -> 0.2577672 | V6: Dividends Kings ETF | W6: {=TEXTJOIN(", ", TRUE, IF($A:$A=V6, $B:$B&" ("&TEXT($C:$C,"0.00%")&")", ""))} -> SCHD (25.78%) | X6: =IFERROR(SUMIF($A$2:$A22,V6,$E$2:$E22),"") -> 20859.452 | Y6: =IFERROR(SUMIF($A$2:$A22,V6,$F$2:$F22),"") -> 19997.33 | Z6: =IFERROR(SUMIF($A$2:$A22,V6,$J$2:$J22),"") -> 665.7272 | AA6: =(X6-Y6)/Y6 -> 0.043111861 | AB6: =IFERROR(SUMIF($A$2:$A22,V6,$N$2:$N22),"") -> 12.515671 | AC6: =Z6/Y6 -> 0.033290804
A7: International | B7: VXUS | C7: =E7/$Q$16 -> 0.066114869 | D7: 63.3466 | E7: =IFERROR(__xludf.DUMMYFUNCTION("(GOOGLEFINANCE(B7)*D7)"),5350.253836) -> 5350.2538 | F7: 5269.76 | G7: =IFERROR(VLOOKUP(B7,'Stock Stats'!$A:$M,6,false),"") -> 0.025929434 | H7: =IFERROR(VLOOKUP(B7,'Stock Stats'!$A:$M,8,false),"") -> 0.1204 | I7: etf | J7: =((E7*G7)) -> 138.72905 | K7: =IF(I7="mutf","https://stockanalysis.com/quote/"&I7&"/"&B7&"/dividend/","https://stockanalysis.com/"&I7&"/"&B7&"/dividend/") -> https://stockanalysis.com/etf/VXUS/dividend/ | L7: =(E7-F7)/F7 -> 0.015274668 | M7: Charles Schwab | N7: =IFERROR(E7*VLOOKUP(B7,'Stock Stats'!$A:$M,11,false),"") -> 2.6751269 | O7: 6 | U7: =IFERROR(SUMIF($A$2:$A23,V7,$C$2:$C23),"") -> 0.066114869 | V7: International | W7: {=TEXTJOIN(", ", TRUE, IF($A:$A=V7, $B:$B&" ("&TEXT($C:$C,"0.00%")&")", ""))} -> VXUS (6.61%) | X7: =IFERROR(SUMIF($A$2:$A23,V7,$E$2:$E23),"") -> 5350.2538 | Y7: =IFERROR(SUMIF($A$2:$A23,V7,$F$2:$F23),"") -> 5269.76 | Z7: =IFERROR(SUMIF($A$2:$A23,V7,$J$2:$J23),"") -> 138.72905 | AA7: =(X7-Y7)/Y7 -> 0.015274668 | AB7: =IFERROR(SUMIF($A$2:$A23,V7,$N$2:$N23),"") -> 2.6751269 | AC7: =Z7/Y7 -> 0.026325498
Q14: Cash | R14: 3.49
Q15: Total Worth | R15: Total Paid | S15: Return
Q16: =SUM($E$2:$E18)+R14 -> 80923.609 | R16: =SUM(F2:F18)+R14 -> 78339.52 | S16: =(Q16-R16)/R16 -> 0.032985769
S17: =Q16-R16 -> 2584.0893

Sheet Stock Stats
A1: Ticker | B1: Sleeve | C1: Sector | D1: Type | E1: Link | F1: Dividend Yield | G1: Annual Dividend | H1: Dividend Growth | I1: Payout Ratio | J1: Growth Years | K1: Expense Ratio | L1: AFFO per Share | M1: AFFO payout Ratio
A2: META | B2: MAG 7 | C2: Communication | D2: stocks | E2: =IF(D2="mutf","https://stockanalysis.com/quote/"&D2&"/"&A2&"/dividend/","https://stockanalysis.com/"&D2&"/"&A2&"/dividend/") -> https://stockanalysis.com/stocks/META/dividend/ | F2: =IFERROR(__xludf.DUMMYFUNCTION("IFERROR(G2/GOOGLEFINANCE(A2,""price""),""0.00%"")"),0.003348374443930673) -> 0.0033483744 | G2: 2.1 | H2: 0.0244 | I2: 0.0764 | J2: 1 | K2: 0
A3: COST | B3: Dividend Income | C3: Consumer Staples | D3: stocks | E3: =IF(D3="mutf","https://stockanalysis.com/quote/"&D3&"/"&A3&"/dividend/","https://stockanalysis.com/"&D3&"/"&A3&"/dividend/") -> https://stockanalysis.com/stocks/COST/dividend/ | F3: =IFERROR(__xludf.DUMMYFUNCTION("IFERROR(G3/GOOGLEFINANCE(A3,""price""),""0.00%"")"),0.005790943697361185) -> 0.0057909437 | G3: 5.37 | H3: 0.126 | I3: 0.2787 | J3: 1 | K3: 0
A4: NVDA | B4: MAG 7 | C4: Semiconductors | D4: stocks | E4: =IF(D4="mutf","https://stockanalysis.com/quote/"&D4&"/"&A4&"/dividend/","https://stockanalysis.com/"&D4&"/"&A4&"/dividend/") -> https://stockanalysis.com/stocks/NVDA/dividend/ | F4: =IFERROR(__xludf.DUMMYFUNCTION("IFERROR(G4/GOOGLEFINANCE(A4,""price""),""0.00%"")"),1.8862586060548902E-4) -> 0.00018862586 | G4: 0.04 | H4: 6 | I4: 0.0429 | J4: 2 | K4: 0
A5: ASML | B5: Speculative | C5: Semiconductors | D5: stocks | E5: =IF(D5="mutf","https://stockanalysis.com/quote/"&D5&"/"&A5&"/dividend/","https://stockanalysis.com/"&D5&"/"&A5&"/dividend/") -> https://stockanalysis.com/stocks/ASML/dividend/ | F5: =IFERROR(__xludf.DUMMYFUNCTION("IFERROR(G5/GOOGLEFINANCE(A5,""price""),""0.00%"")"),0.0023864229185397313) -> 0.0023864229 | G5: 4.3 | H5: 0.2649 | I5: 0.2507 | J5: 2 | K5: 0
A6: ENB | B6: Dividend Income | C6: Energy & Oil | D6: stocks | E6: =IF(D6="mutf","https://stockanalysis.com/quote/"&D6&"/"&A6&"/dividend/","https://stockanalysis.com/"&D6&"/"&A6&"/dividend/") -> https://stockanalysis.com/stocks/ENB/dividend/ | F6: =IFERROR(__xludf.DUMMYFUNCTION("IFERROR(G6/GOOGLEFINANCE(A6,""price""),""0.00%"")"),0.06755555555555555) -> 0.067555556 | G6: 3.8 | H6: 0.0433 | I6: 1.3123 | J6: 2 | K6: 0
A7: BTI | B7: Dividend Income | C7: Tobacco | D7: stocks | E7: =IF(D7="mutf","https://stockanalysis.com/quote/"&D7&"/"&A7&"/dividend/","https://stockanalysis.com/"&D7&"/"&A7&"/dividend/") -> https://stockanalysis.com/stocks/BTI/dividend/ | F7: =IFERROR(__xludf.DUMMYFUNCTION("IFERROR(G7/GOOGLEFINANCE(A7,""price""),""0.00%"")"),0.039477924589107316) -> 0.039477925 | G7: 2.45 | H7: 0.0487 | I7: 0.6813 | J7: 3 | K7: 0
A8: MAIN | B8: REITs & BDCs | C8: BDCs | D8: stocks | E8: =IF(D8="mutf","https://stockanalysis.com/quote/"&D8&"/"&A8&"/dividend/","https://stockanalysis.com/"&D8&"/"&A8&"/dividend/") -> https://stockanalysis.com/stocks/MAIN/dividend/ | F8: =IFERROR(__xludf.DUMMYFUNCTION("IFERROR(G8/GOOGLEFINANCE(A8,""price""),""0.00%"")"),0.05704697986577181) -> 0.05704698 | G8: 3.06 | H8: 0.0286 | I8: 0.9084 | J8: 5 | K8: 0
A9: VICI | B9: REITs & BDCs | C9: Real Estate | D9: stocks | E9: =IF(D9="mutf","https://stockanalysis.com/quote/"&D9&"/"&A9&"/dividend/","https://stockanalysis.com/"&D9&"/"&A9&"/dividend/") -> https://stockanalysis.com/stocks/VICI/dividend/ | F9: =IFERROR(__xludf.DUMMYFUNCTION("IFERROR(G9/GOOGLEFINANCE(A9,""price""),""0.00%"")"),0.06708051166290444) -> 0.067080512 | G9: 1.783 | H9: 0.0405 | I9: 0.6176 | J9: 7 | K9: 0 | L9: 2.45 | M9: =G9/L9 -> 0.7277551
A10: EQIX | B10: REITs & BDCs | C10: Real Estate | D10: stocks | E10: =IF(D10="mutf","https://stockanalysis.com/quote/"&D10&"/"&A10&"/dividend/","https://stockanalysis.com/"&D10&"/"&A10&"/dividend/") -> https://stockanalysis.com/stocks/EQIX/dividend/ | F10: =IFERROR(__xludf.DUMMYFUNCTION("IFERROR(G10/GOOGLEFINANCE(A10,""price""),""0.00%"")"),0.0186927697960612) -> 0.01869277 | G10: 19.23 | H10: 0.1006 | I10: 1.3621 | J10: 9 | K10: 0 | L10: 42.5 | M10: =G10/L10 -> 0.45247059
A11: PLD | B11: REITs & BDCs | C11: Real Estate | D11: stocks | E11: =IF(D11="mutf","https://stockanalysis.com/quote/"&D11&"/"&A11&"/dividend/","https://stockanalysis.com/"&D11&"/"&A11&"/dividend/") -> https://stockanalysis.com/stocks/PLD/dividend/ | F11: =IFERROR(__xludf.DUMMYFUNCTION("IFERROR(G11/GOOGLEFINANCE(A11,""price""),""0.00%"")"),0.028749136143745684) -> 0.028749136 | G11: 4.16 | H11: 0.0558 | I11: 1.0476 | J11: 12 | K11: 0 | L11: 6.27 | M11: =G11/L11 -> 0.66347687
A12: MA | B12: Dividend Income | C12: Finance | D12: stocks | E12: =IF(D12="mutf","https://stockanalysis.com/quote/"&D12&"/"&A12&"/dividend/","https://stockanalysis.com/"&D12&"/"&A12&"/dividend/") -> https://stockanalysis.com/stocks/MA/dividend/ | F12: =IFERROR(__xludf.DUMMYFUNCTION("IFERROR(G12/GOOGLEFINANCE(A12,""price""),""0.00%"")"),0.006128049926688973) -> 0.0061280499 | G12: 3.26 | H12: 0.1463 | I12: 0.195 | J12: 14 | K12: 0
A13: AAPL | B13: MAG 7 | C13: Information Technology | D13: stocks | E13: =IF(D13="mutf","https://stockanalysis.com/quote/"&D13&"/"&A13&"/dividend/","https://stockanalysis.com/"&D13&"/"&A13&"/dividend/") -> https://stockanalysis.com/stocks/AAPL/dividend/ | F13: =IFERROR(__xludf.DUMMYFUNCTION("IFERROR(G13/GOOGLEFINANCE(A13,""price""),""0.00%"")"),0.003191260854889687) -> 0.0031912609 | G13: 1.04 | H13: 0.0396 | I13: 0.1273 | J13: 14 | K13: 0
A14: AVGO | B14: Speculative | C14: Semiconductors | D14: stocks | E14: =IF(D14="mutf","https://stockanalysis.com/quote/"&D14&"/"&A14&"/dividend/","https://stockanalysis.com/"&D14&"/"&A14&"/dividend/") -> https://stockanalysis.com/stocks/AVGO/dividend/ | F14: =IFERROR(__xludf.DUMMYFUNCTION("IFERROR(G14/GOOGLEFINANCE(A14,""price""),""0.00%"")"),0.0064010483606763945) -> 0.0064010484 | G14: 2.54 | H14: 0.1043 | I14: 0.4227 | J14: 15 | K14: 0
A15: JPM | B15: Dividend Income | C15: Finance | D15: stocks | E15: =IF(D15="mutf","https://stockanalysis.com/quote/"&D15&"/"&A15&"/dividend/","https://stockanalysis.com/"&D15&"/"&A15&"/dividend/") -> https://stockanalysis.com/stocks/JPM/dividend/ | F15: =IFERROR(__xludf.DUMMYFUNCTION("IFERROR(G15/GOOGLEFINANCE(A15,""price""),""0.00%"")"),0.017230981304385287) -> 0.017230981 | G15: 6 | H15: 0.1321 | I15: 0.2874 | J15: 15 | K15: 0
A16: UNH | B16: Dividend Income | C16: Health | D16: stocks | E16: =IF(D16="mutf","https://stockanalysis.com/quote/"&D16&"/"&A16&"/dividend/","https://stockanalysis.com/"&D16&"/"&A16&"/dividend/") -> https://stockanalysis.com/stocks/UNH/dividend/ | F16: =IFERROR(__xludf.DUMMYFUNCTION("IFERROR(G16/GOOGLEFINANCE(A16,""price""),""0.00%"")"),0.02049569914910389) -> 0.020495699 | G16: 8.84 | H16: 0.0517 | I16: 0.6755 | J16: 16 | K16: 0
A17: V | B17: Dividend Income | C17: Finance | D17: stocks | E17: =IF(D17="mutf","https://stockanalysis.com/quote/"&D17&"/"&A17&"/dividend/","https://stockanalysis.com/"&D17&"/"&A17&"/dividend/") -> https://stockanalysis.com/stocks/V/dividend/ | F17: =IFERROR(__xludf.DUMMYFUNCTION("IFERROR(G17/GOOGLEFINANCE(A17,""price""),""0.00%"")"),0.007583045668043687) -> 0.0075830457 | G17: 2.68 | H17: 0.2267 | I17: 0.1354 | J17: 17 | K17: 0
A18: PM | B18: Dividend Income | C18: Tobacco | D18: stocks | E18: =IF(D18="mutf","https://stockanalysis.com/quote/"&D18&"/"&A18&"/dividend/","https://stockanalysis.com/"&D18&"/"&A18&"/dividend/") -> https://stockanalysis.com/stocks/PM/dividend/ | F18: =IFERROR(__xludf.DUMMYFUNCTION("IFERROR(G18/GOOGLEFINANCE(A18,""price""),""0.00%"")"),0.029644879053010807) -> 0.029644879 | G18: 5.76 | H18: 0.0889 | I18: 0.8282 | J18: 17 | K18: 0
A19: MSFT | B19: MAG 7 | C19: Information Technology | D19: stocks | E19: =IF(D19="mutf","https://stockanalysis.com/quote/"&D19&"/"&A19&"/dividend/","https://stockanalysis.com/"&D19&"/"&A19&"/dividend/") -> https://stockanalysis.com/stocks/MSFT/dividend/ | F19: =IFERROR(__xludf.DUMMYFUNCTION("IFERROR(G19/GOOGLEFINANCE(A19,""price""),""0.00%"")"),0.00686580929446124) -> 0.0068658093 | G19: 2.68 | H19: 0.0964 | I19: 0.2168 | J19: 20 | K19: 0
A20: O | B20: REITs & BDCs | C20: Real Estate | D20: stocks | E20: =IF(D20="mutf","https://stockanalysis.com/quote/"&D20&"/"&A20&"/dividend/","https://stockanalysis.com/"&D20&"/"&A20&"/dividend/") -> https://stockanalysis.com/stocks/O/dividend/ | F20: =IFERROR(__xludf.DUMMYFUNCTION("IFERROR(G20/GOOGLEFINANCE(A20,""price""),""0.00%"")"),0.049730893433799786) -> 0.049730893 | G20: 3.234 | H20: 0.015 | I20: 2.656 | J20: 22 | K20: 0 | L20: 4.43 | M20: =3.25/L20 -> 0.73363431
A21: IBM | B21: Speculative | C21: Information Technology | D21: stocks | E21: =IF(D21="mutf","https://stockanalysis.com/quote/"&D21&"/"&A21&"/dividend/","https://stockanalysis.com/"&D21&"/"&A21&"/dividend/") -> https://stockanalysis.com/stocks/IBM/dividend/ | F21: =IFERROR(__xludf.DUMMYFUNCTION("IFERROR(G21/GOOGLEFINANCE(A21,""price""),""0.00%"")"),0.03285221363658453) -> 0.032852214 | G21: 6.76 | H21: 0.006 | I21: 0.595 | J21: 30 | K21: 0
A22: NNN | B22: REITs & BDCs | C22: Real Estate | D22: stocks | E22: =IF(D22="mutf","https://stockanalysis.com/quote/"&D22&"/"&A22&"/dividend/","https://stockanalysis.com/"&D22&"/"&A22&"/dividend/") -> https://stockanalysis.com/stocks/NNN/dividend/ | F22: =IFERROR(__xludf.DUMMYFUNCTION("IFERROR(G22/GOOGLEFINANCE(A22,""price""),""0.00%"")"),0.04900959771288544) -> 0.049009598 | G22: 2.4 | H22: 0.0345 | I22: 1.1682 | J22: 37 | K22: 0 | L22: 3.57 | M22: =2.4/L22 -> 0.67226891
A23: CVX | B23: Dividend Income | C23: Energy & Oil | D23: stocks | E23: =IF(D23="mutf","https://stockanalysis.com/quote/"&D23&"/"&A23&"/dividend/","https://stockanalysis.com/"&D23&"/"&A23&"/dividend/") -> https://stockanalysis.com/stocks/CVX/dividend/ | F23: =IFERROR(__xludf.DUMMYFUNCTION("IFERROR(G23/GOOGLEFINANCE(A23,""price""),""0.00%"")"),0.036895015027463986) -> 0.036895015 | G23: 7.12 | H23: 0.0449 | I23: 1.2142 | J23: 39 | K23: 0
A24: SPGI | B24: YoC Dividend Growth | C24: Finance | D24: stocks | E24: =IF(D24="mutf","https://stockanalysis.com/quote/"&D24&"/"&A24&"/dividend/","https://stockanalysis.com/"&D24&"/"&A24&"/dividend/") -> https://stockanalysis.com/stocks/SPGI/dividend/ | F24: =IFERROR(__xludf.DUMMYFUNCTION("IFERROR(G24/GOOGLEFINANCE(A24,""price""),""0.00%"")"),0.009043024285647695) -> 0.0090430243 | G24: 3.88 | H24: 0.0211 | I24: 0.245 | J24: 53 | K24: 0
A25: ABBV | B25: Dividend Income | C25: Health | D25: stocks | E25: =IF(D25="mutf","https://stockanalysis.com/quote/"&D25&"/"&A25&"/dividend/","https://stockanalysis.com/"&D25&"/"&A25&"/dividend/") -> https://stockanalysis.com/stocks/ABBV/dividend/ | F25: =IFERROR(__xludf.DUMMYFUNCTION("IFERROR(G25/GOOGLEFINANCE(A25,""price""),""0.00%"")"),0.027319384129490722) -> 0.027319384 | G25: 6.92 | H25: 0.0556 | I25: 3.3644 | J25: 54 | K25: 0
A26: ABT | B26: Dividend Income | C26: Health | D26: stocks | E26: =IF(D26="mutf","https://stockanalysis.com/quote/"&D26&"/"&A26&"/dividend/","https://stockanalysis.com/"&D26&"/"&A26&"/dividend/") -> https://stockanalysis.com/stocks/ABT/dividend/ | F26: =IFERROR(__xludf.DUMMYFUNCTION("IFERROR(G26/GOOGLEFINANCE(A26,""price""),""0.00%"")"),0.025057174107586757) -> 0.025057174 | G26: 2.52 | H26: 0.069 | I26: 0.6947 | J26: 54 | K26: 0
A27: FXAIX | B27: S&P 500 | C27: S&P 500 | D27: mutf | E27: =IF(D27="mutf","https://stockanalysis.com/quote/"&D27&"/"&A27&"/dividend/","https://stockanalysis.com/"&D27&"/"&A27&"/dividend/") -> https://stockanalysis.com/quote/mutf/FXAIX/dividend/ | F27: =IFERROR(__xludf.DUMMYFUNCTION("IFERROR(G27/GOOGLEFINANCE(A27,""price""),""0.00%"")"),0.010575117820606153) -> 0.010575118 | G27: 2.76 | H27: 0.051 | K27: 0.00015
A28: VEA | B28: International | C28: Developed Markets | D28: etf | E28: =IF(D28="mutf","https://stockanalysis.com/quote/"&D28&"/"&A28&"/dividend/","https://stockanalysis.com/"&D28&"/"&A28&"/dividend/") -> https://stockanalysis.com/etf/VEA/dividend/ | F28: =IFERROR(__xludf.DUMMYFUNCTION("IFERROR(G28/GOOGLEFINANCE(A28,""price""),""0.00%"")"),0.0256774010497943) -> 0.025677401 | G28: 1.81 | H28: 0.1772 | I28: 0.4613 | K28: 0.0003
A29: MU | B29: Speculative | C29: Semiconductors | D29: stocks | E29: =IF(D29="mutf","https://stockanalysis.com/quote/"&D29&"/"&A29&"/dividend/","https://stockanalysis.com/"&D29&"/"&A29&"/dividend/") -> https://stockanalysis.com/stocks/MU/dividend/ | F29: =IFERROR(__xludf.DUMMYFUNCTION("IFERROR(G29/GOOGLEFINANCE(A29,""price""),""0.00%"")"),0.0027931796389711093) -> 0.0027931796 | G29: 2.68 | H29: 0.1522 | I29: 0.012 | K29: 0
A30: QTUM | B30: Concentrated Tech | C30: Quantum | D30: etf | E30: =IF(D30="mutf","https://stockanalysis.com/quote/"&D30&"/"&A30&"/dividend/","https://stockanalysis.com/"&D30&"/"&A30&"/dividend/") -> https://stockanalysis.com/etf/QTUM/dividend/ | F30: =IFERROR(__xludf.DUMMYFUNCTION("IFERROR(G30/GOOGLEFINANCE(A30,""price""),""0.00%"")"),0.008147483256231443) -> 0.0081474833 | G30: 1.18 | H30: 0.9109 | I30: 0.2822 | K30: 0.004
A31: AMZN | B31: MAG 7 | C31: Information Technology | D31: stocks | E31: =IF(D31="mutf","https://stockanalysis.com/quote/"&D31&"/"&A31&"/dividend/","https://stockanalysis.com/"&D31&"/"&A31&"/dividend/") -> https://stockanalysis.com/stocks/AMZN/dividend/ | F31: =IFERROR(__xludf.DUMMYFUNCTION("IFERROR(G31/GOOGLEFINANCE(A31,""price""),""0.00%"")"),0.0) -> 0 | G31: 0 | H31: 0 | I31: 0 | K31: 0
A32: GOOGL | B32: MAG 7 | C32: Communication | D32: stocks | E32: =IF(D32="mutf","https://stockanalysis.com/quote/"&D32&"/"&A32&"/dividend/","https://stockanalysis.com/"&D32&"/"&A32&"/dividend/") -> https://stockanalysis.com/stocks/GOOGL/dividend/ | F32: =IFERROR(__xludf.DUMMYFUNCTION("IFERROR(G32/GOOGLEFINANCE(A32,""price""),""0.00%"")"),0.0025724224619252246) -> 0.0025724225 | G32: 0.88 | H32: 0.0494 | I32: 0.0648 | K32: 0
A33: SCHD | B33: Dividend Equity | C33: Dividend Growth | D33: etf | E33: =IF(D33="mutf","https://stockanalysis.com/quote/"&D33&"/"&A33&"/dividend/","https://stockanalysis.com/"&D33&"/"&A33&"/dividend/") -> https://stockanalysis.com/etf/SCHD/dividend/ | F33: =IFERROR(__xludf.DUMMYFUNCTION("IFERROR(G33/GOOGLEFINANCE(A33,""price""),""0.00%"")"),0.03191489361702128) -> 0.031914894 | G33: 1.05 | H33: 0.0224 | I33: 0.5558 | K33: 0.0006
A34: PLTR | B34: Software Infrastructure | C34: Software Infrastructure | D34: stocks | E34: =IF(D34="mutf","https://stockanalysis.com/quote/"&D34&"/"&A34&"/dividend/","https://stockanalysis.com/"&D34&"/"&A34&"/dividend/") -> https://stockanalysis.com/stocks/PLTR/dividend/ | F34: =IFERROR(__xludf.DUMMYFUNCTION("IFERROR(G34/GOOGLEFINANCE(A34,""price""),""0.00%"")"),0.0) -> 0 | G34: 0 | H34: 0 | I34: 0 | K34: 0
A35: VOO | B35: S&P 500 | C35: S&P 500 | D35: etf | E35: =IF(D35="mutf","https://stockanalysis.com/quote/"&D35&"/"&A35&"/dividend/","https://stockanalysis.com/"&D35&"/"&A35&"/dividend/") -> https://stockanalysis.com/etf/VOO/dividend/ | F35: =IFERROR(__xludf.DUMMYFUNCTION("IFERROR(G35/GOOGLEFINANCE(A35,""price""),""0.00%"")"),0.010698222785031221) -> 0.010698223 | G35: 7.35 | H35: 0.0594 | I35: 0.2988 | K35: 0.0003
A36: RKLB | B36: Aerospace / Defense | C36: Aerospace | D36: stocks | E36: =IF(D36="mutf","https://stockanalysis.com/quote/"&D36&"/"&A36&"/dividend/","https://stockanalysis.com/"&D36&"/"&A36&"/dividend/") -> https://stockanalysis.com/stocks/RKLB/dividend/ | F36: =IFERROR(__xludf.DUMMYFUNCTION("IFERROR(G36/GOOGLEFINANCE(A36,""price""),""0.00%"")"),0.0) -> 0 | G36: 0 | H36: 0 | I36: 0 | K36: 0
A37: QQQM | B37: Concentrated Tech | C37: NASDAQ 100 | D37: etf | E37: =IF(D37="mutf","https://stockanalysis.com/quote/"&D37&"/"&A37&"/dividend/","https://stockanalysis.com/"&D37&"/"&A37&"/dividend/") -> https://stockanalysis.com/etf/QQQM/dividend/ | F37: =IFERROR(__xludf.DUMMYFUNCTION("IFERROR(G37/GOOGLEFINANCE(A37,""price""),""0.00%"")"),0.004510708628882309) -> 0.0045107086 | G37: 1.31 | H37: 0.0494 | I37: 0.1604 | K37: 0.0015
A38: VWO | B38: International | C38: Emerging Markets | D38: etf | E38: =IF(D38="mutf","https://stockanalysis.com/quote/"&D38&"/"&A38&"/dividend/","https://stockanalysis.com/"&D38&"/"&A38&"/dividend/") -> https://stockanalysis.com/etf/VWO/dividend/ | F38: =IFERROR(__xludf.DUMMYFUNCTION("IFERROR(G38/GOOGLEFINANCE(A38,""price""),""0.00%"")"),0.023465397041319502) -> 0.023465397 | G38: 1.38 | H38: -0.0017 | I38: 0.3979 | K38: 0.0006
A39: IONQ | B39: Speculative | C39: Quantum | D39: stocks | E39: =IF(D39="mutf","https://stockanalysis.com/quote/"&D39&"/"&A39&"/dividend/","https://stockanalysis.com/"&D39&"/"&A39&"/dividend/") -> https://stockanalysis.com/stocks/IONQ/dividend/ | F39: =IFERROR(__xludf.DUMMYFUNCTION("IFERROR(G39/GOOGLEFINANCE(A39,""price""),""0.00%"")"),0.0) -> 0 | G39: 0 | H39: 0 | I39: 0 | K39: 0
A40: VGT | B40: Concentrated Tech | C40: Information Technology | D40: etf | E40: =IF(D40="mutf","https://stockanalysis.com/quote/"&D40&"/"&A40&"/dividend/","https://stockanalysis.com/"&D40&"/"&A40&"/dividend/") -> https://stockanalysis.com/etf/VGT/dividend/ | F40: =IFERROR(__xludf.DUMMYFUNCTION("IFERROR(G40/GOOGLEFINANCE(A40,""price""),""0.00%"")"),0.003719079743988929) -> 0.0037190797 | G40: 0.43 | H40: 0.109 | I40: 0.1506 | K40: 0.0009
...
